<?xml version="1.0" ?>
<robot name="grasp">
	
  
	<link name="virtual_base">
		
    
		<inertial>
			
      
			<mass value="1e-10"/>
			
      
			<inertia ixx="1e-10" ixy="0" ixz="0" iyy="1e-10" iyz="0" izz="1e-10"/>
			
    
		</inertial>
		
  
	</link>
	

  
	<link name="link_climbing_hold_vhacd_convex_0">
		<inertial>
			<origin rpy="-3.1363 0.0109355 2.02168" xyz="0.0349573 -0.0137936 -0.0219599"/>
			<mass value="2.81E-04"/>
			<inertia ixx="2.68E-07" ixy="-7.36E-10" ixz="-1.09E-09" iyy="2.19E-07" iyz="-6.41E-09" izz="2.07E-07"/>
		</inertial>
		<visual>
			<origin rpy="-3.1363 0.0109355 2.02168" xyz="0.0349573 -0.0137936 -0.0219599"/>
			<geometry>
				<mesh filename="../example/mini_dexnet/urdf/climbing_hold/climbing_hold_vhacd_convex_0.obj"/>
			</geometry>
			<material name="">
				<color rgba="0.75 0.75 0.75 1"/>
			</material>
		</visual>
		<collision>
			<origin rpy="-3.1363 0.0109355 2.02168" xyz="0.0349573 -0.0137936 -0.0219599"/>
			<geometry>
				<mesh filename="../example/mini_dexnet/urdf/climbing_hold/climbing_hold_vhacd_convex_0.obj"/>
			</geometry>
		</collision>
	</link>
	<joint name="world_joint" type="fixed">
		
    
		<origin rpy="0 1.57079632679 0" xyz="0 0 -0.03"/>
		
    
		<parent link="virtual_base"/>
		
    
		<child link="right_gripper_base"/>
		
  
	</joint>
	

  
  
	<link name="right_gripper_base">
		
    
		<visual>
			
      
			<origin rpy="-1.57079632679 3.14159265359 0" xyz="0 0 0"/>
			
      
			<geometry>
				
        
				<mesh filename="../../rethink_ee_description/meshes/electric_gripper/electric_gripper_base.STL"/>
				
      
			</geometry>
			
      
			<material name="darkred_red">
				
        
				<color rgba=".5 0 0 1"/>
				
      
			</material>
			
    
		</visual>
		
    
		<collision>
			
      
			<origin rpy="-1.57079632679 3.14159265359 0" xyz="0.0 0.0 0"/>
			
      
			<geometry>
				
        
				<mesh filename="../../rethink_ee_description/meshes/electric_gripper/electric_gripper_base.STL"/>
				
      
			</geometry>
			
    
		</collision>
		
    
		<inertial>
			
      
			<origin rpy="-1.57079632679 3.14159265359 0" xyz="0.0 0.0 0.0"/>
			
      
			<mass value="0.3"/>
			
      
			<inertia ixx="2e-08" ixy="0" ixz="0" iyy="3e-08" iyz="0" izz="2e-08"/>
			
    
		</inertial>
		
  
	</link>
	
  
	<link name="r_gripper_l_finger">
		
    
		<visual>
			
      
			<origin rpy="0 0 -3.14159265359" xyz="0 0 0"/>
			
      
			<geometry>
				
        
				<mesh filename="../../rethink_ee_description/meshes/electric_gripper/fingers/standard_narrow.STL"/>
				
      
			</geometry>
			
      
			<material name="darkred_grey">
				
        
				<color rgba=".2 .2 .2 1"/>
				
      
			</material>
			
    
		</visual>
		
    
		<collision>
			
      
			<origin rpy="0 0 -3.14159265359" xyz="0 0 0"/>
			
      
			<geometry>
				
        
				<mesh filename="../../rethink_ee_description/meshes/electric_gripper/fingers/standard_narrow.STL"/>
				
      
			</geometry>
			
    
		</collision>
		
    
		<inertial>
			
      
			<origin rpy="0 0 -3.14159265359" xyz="0 0 0"/>
			
      
			<mass value="0.02"/>
			
      
			<inertia ixx="0.01" ixy="0" ixz="0" iyy="0.01" iyz="0" izz="0.01"/>
			
    
		</inertial>
		
  
	</link>
	
  
	<gazebo reference="r_gripper_l_finger">
		
    
		<mu1>1000</mu1>
		
    
		<mu2>1000</mu2>
		
    
		<fdir1>0.0 0.0 1.0</fdir1>
		
    
		<kp>1e5</kp>
		
    
		<kd>1.0</kd>
		
  
	</gazebo>
	
  
  
	<link name="r_gripper_r_finger">
		
    
		<visual>
			
      
			<origin rpy="0 0 -0.0" xyz="0 0 0"/>
			
      
			<geometry>
				
        
				<mesh filename="../../rethink_ee_description/meshes/electric_gripper/fingers/standard_narrow.STL"/>
				
      
			</geometry>
			
      
			<material name="darkred_grey">
				
        
				<color rgba=".2 .2 .2 1"/>
				
      
			</material>
			
    
		</visual>
		
    
		<collision>
			
      
			<origin rpy="0 0 -0.0" xyz="0 0 0"/>
			
      
			<geometry>
				
        
				<mesh filename="../../rethink_ee_description/meshes/electric_gripper/fingers/standard_narrow.STL"/>
				
      
			</geometry>
			
    
		</collision>
		
    
		<inertial>
			
      
			<origin rpy="0 0 -0.0" xyz="0 0 0"/>
			
      
			<mass value="0.02"/>
			
      
			<inertia ixx="0.01" ixy="0" ixz="0" iyy="0.01" iyz="0" izz="0.01"/>
			
    
		</inertial>
		
  
	</link>
	
  
	<gazebo reference="r_gripper_r_finger">
		
    
		<mu1>1000</mu1>
		
    
		<mu2>1000</mu2>
		
    
		<fdir1>0.0 0.0 1.0</fdir1>
		
    
		<kp>1e5</kp>
		
    
		<kd>1.0</kd>
		
  
	</gazebo>
	
  
  
 
  
  
	<joint name="right_endpoint" type="fixed">
		
    
		<origin rpy="0 0 0" xyz="0 0 0.1327"/>
		
    
		<parent link="right_gripper_base"/>
		
    
		<child link="right_gripper"/>
		
  
	</joint>
	
  
  
	<link name="right_gripper">
		
    
		<inertial>
			
      
			<origin rpy="0 0 0" xyz="0 0 0"/>
			
      
			<mass value="0.0001"/>
			
      
			<inertia ixx="0" ixy="0" ixz="0" iyy="0" iyz="0" izz="0.0"/>
			
    
		</inertial>
		
  
	</link>
	
  
	<joint name="r_gripper_l_finger_joint" type="prismatic">
		
    
		<origin rpy="0 0 0" xyz="0.0 -0.0015 0.02"/>
		
    
		<axis xyz="0 1 0"/>
		
    
		<parent link="right_gripper_base"/>
		
    
		<child link="r_gripper_l_finger"/>
		
    
		<limit effort="20.0" lower="0.0" upper="0.020833" velocity="5.0"/>
		
    
		<dynamics damping="0.7" friction="0.0"/>
		
  
	</joint>
	
  
	<joint name="r_gripper_r_finger_joint" type="prismatic">
		
    
		<origin rpy="0 0 0" xyz="0.0 0.0015 0.02"/>
		
    
		<axis xyz="0 1 0"/>
		
    
		<parent link="right_gripper_base"/>
		
    
		<child link="r_gripper_r_finger"/>
		
    
		<limit effort="20.0" lower="-0.020833" upper="0.0" velocity="5.0"/>
		
    
		<mimic joint="r_gripper_l_finger_joint" multiplier="-1.0"/>
		
    
		<dynamics damping="0.7" friction="0.0"/>
		
  
	</joint>
	
  
	<transmission name="gripper_right1">
		
    
		<type>transmission_interface/SimpleTransmission</type>
		
    
		<joint name="r_gripper_r_finger_joint">
			
      
			<hardwareInterface>EffortJointInterface</hardwareInterface>
			
    
		</joint>
		
    
		<actuator name="gripper_r1_motor1">
			
      
			<hardwareInterface>EffortJointInterface</hardwareInterface>
			
      
			<mechanicalReduction>1</mechanicalReduction>
			
    
		</actuator>
		
  
	</transmission>
	
  
	<transmission name="gripper_right2">
		
    
		<type>transmission_interface/SimpleTransmission</type>
		
    
		<joint name="r_gripper_l_finger_joint">
			
      
			<hardwareInterface>EffortJointInterface</hardwareInterface>
			
    
		</joint>
		
    
		<actuator name="gripper_r1_motor2">
			
      
			<hardwareInterface>EffortJointInterface</hardwareInterface>
			
      
			<mechanicalReduction>1</mechanicalReduction>
			
    
		</actuator>
		
  
	</transmission>
	
  
	<gazebo reference="r_gripper_r_finger_joint">
		
    
		<implicitSpringDamper>1</implicitSpringDamper>
		
  
	</gazebo>
	
  
	<gazebo reference="r_gripper_l_finger_joint">
		
    
		<implicitSpringDamper>1</implicitSpringDamper>
		
  
	</gazebo>
	

	<joint name="grasp_joint" type="fixed">
		<origin rpy="0 0 0" xyz="0 0 0"/>
		<parent link="virtual_base"/>
		<child link="link_climbing_hold_vhacd_convex_0"/>
	</joint>
</robot>
